2025-04-07 00:13:42,436 - config.logging_config - INFO - Starting Bolsover District Council application
2025-04-07 00:13:42,438 - ui.pages.home - INFO - Loading home page...
2025-04-07 00:13:42,438 - ui.pages.home - INFO - Setting background image from: src/img/background_img.png
2025-04-07 00:13:42,438 - ui.pages.home - INFO - Loading image file from: src/img/background_img.png
2025-04-07 00:13:42,447 - ui.pages.home - INFO - Successfully loaded image: src/img/background_img.png
2025-04-07 00:13:43,017 - ui.pages.home - INFO - Background image set successfully from: src/img/background_img.png
2025-04-07 00:13:43,018 - ui.pages.home - INFO - Applying custom CSS for layout and button styling...
2025-04-07 00:13:43,018 - ui.pages.home - INFO - Loading logo image from: src/img/Bolsover_District_Council_logo.png
2025-04-07 00:13:43,021 - ui.pages.home - INFO - Loading image file from: src/img/Bolsover_District_Council_logo.png
2025-04-07 00:13:43,024 - ui.pages.home - INFO - Successfully loaded image: src/img/Bolsover_District_Council_logo.png
2025-04-07 00:13:43,030 - ui.pages.home - INFO - Loading Bolsover image from: src/img/Bolsover.png
2025-04-07 00:13:43,032 - ui.pages.home - INFO - Loading image file from: src/img/Bolsover.png
2025-04-07 00:13:43,203 - ui.pages.home - INFO - Successfully loaded image: src/img/Bolsover.png
2025-04-07 00:13:43,813 - ui.pages.home - INFO - Home page loaded successfully.
2025-04-07 00:14:26,558 - ui.pages.home - INFO - Continue button clicked, navigating to data entry page.
2025-04-07 00:14:26,561 - config.logging_config - INFO - Starting Bolsover District Council application
2025-04-07 00:16:54,517 - config.logging_config - INFO - Starting Bolsover District Council application
2025-04-07 00:16:54,518 - ui.pages.home - INFO - Loading home page...
2025-04-07 00:16:54,519 - ui.pages.home - INFO - Setting background image from: src/img/background_img.png
2025-04-07 00:16:54,519 - ui.pages.home - INFO - Loading image file from: src/img/background_img.png
2025-04-07 00:16:54,525 - ui.pages.home - INFO - Successfully loaded image: src/img/background_img.png
2025-04-07 00:16:54,599 - ui.pages.home - INFO - Background image set successfully from: src/img/background_img.png
2025-04-07 00:16:54,600 - ui.pages.home - INFO - Applying custom CSS for layout and button styling...
2025-04-07 00:16:54,603 - ui.pages.home - INFO - Loading logo image from: src/img/Bolsover_District_Council_logo.png
2025-04-07 00:16:54,603 - ui.pages.home - INFO - Loading image file from: src/img/Bolsover_District_Council_logo.png
2025-04-07 00:16:54,664 - ui.pages.home - INFO - Successfully loaded image: src/img/Bolsover_District_Council_logo.png
2025-04-07 00:16:54,665 - ui.pages.home - INFO - Loading Bolsover image from: src/img/Bolsover.png
2025-04-07 00:16:54,665 - ui.pages.home - INFO - Loading image file from: src/img/Bolsover.png
2025-04-07 00:16:54,785 - ui.pages.home - INFO - Successfully loaded image: src/img/Bolsover.png
2025-04-07 00:16:55,096 - ui.pages.home - INFO - Home page loaded successfully.
2025-04-07 00:17:06,351 - ui.pages.home - INFO - Continue button clicked, navigating to data entry page.
2025-04-07 00:17:06,353 - config.logging_config - INFO - Starting Bolsover District Council application
2025-04-07 00:17:06,396 - ui.pages.data_entry - INFO - Loading data entry page
2025-04-07 00:17:06,398 - ui.pages.data_entry - INFO - Selected data mode: Upload File
2025-04-07 00:17:38,089 - config.logging_config - INFO - Starting Bolsover District Council application
2025-04-07 00:17:38,129 - ui.pages.data_entry - INFO - Loading data entry page
2025-04-07 00:17:38,131 - ui.pages.data_entry - INFO - Selected data mode: Paste Text
2025-04-07 00:17:44,160 - config.logging_config - INFO - Starting Bolsover District Council application
2025-04-07 00:17:44,205 - ui.pages.data_entry - INFO - Loading data entry page
2025-04-07 00:17:44,207 - ui.pages.data_entry - INFO - Selected data mode: Upload File
2025-04-07 00:18:04,143 - config.logging_config - INFO - Starting Bolsover District Council application
2025-04-07 00:18:04,153 - ui.pages.data_entry - INFO - Loading data entry page
2025-04-07 00:18:04,184 - ui.pages.data_entry - INFO - Selected data mode: Upload File
2025-04-07 00:18:06,496 - config.logging_config - INFO - Starting Bolsover District Council application
2025-04-07 00:18:06,504 - ui.pages.data_entry - INFO - Loading data entry page
2025-04-07 00:18:06,506 - ui.pages.data_entry - INFO - Selected data mode: Upload File
2025-04-07 00:18:06,513 - ui.pages.data_entry - INFO - Submit button clicked, processing data...
2025-04-07 00:18:06,620 - ui.pages.data_entry - INFO - 12 files processed successfully.
2025-04-07 00:18:06,622 - ui.pages.data_entry - INFO - Multiple files uploaded, routing to 'aggregated_analysis' page.
2025-04-07 00:18:07,357 - config.logging_config - INFO - Starting Bolsover District Council application
2025-04-07 00:18:08,802 - urllib3.connectionpool - WARNING - Retrying (Retry(total=1, connect=None, read=None, redirect=None, status=None)) after connection broken by 'ReadTimeoutError("HTTPSConnectionPool(host='nominatim.openstreetmap.org', port=443): Read timed out. (read timeout=1)")': /search?q=S44+4RJ%2C+Bolsover+District%2C+UK&format=json&limit=1
2025-04-07 00:18:09,890 - urllib3.connectionpool - WARNING - Retrying (Retry(total=0, connect=None, read=None, redirect=None, status=None)) after connection broken by 'ReadTimeoutError("HTTPSConnectionPool(host='nominatim.openstreetmap.org', port=443): Read timed out. (read timeout=1)")': /search?q=S44+4RJ%2C+Bolsover+District%2C+UK&format=json&limit=1
2025-04-07 00:18:10,964 - processing.geocoding - ERROR - Address geocoding error: HTTPSConnectionPool(host='nominatim.openstreetmap.org', port=443): Max retries exceeded with url: /search?q=S44+4RJ%2C+Bolsover+District%2C+UK&format=json&limit=1 (Caused by ReadTimeoutError("HTTPSConnectionPool(host='nominatim.openstreetmap.org', port=443): Read timed out. (read timeout=1)"))
Traceback (most recent call last):
  File "/Users/apple2015/Documents/Work/Bolsover District Council/Project/.venv/lib/python3.11/site-packages/urllib3/connectionpool.py", line 534, in _make_request
    response = conn.getresponse()
               ^^^^^^^^^^^^^^^^^^
  File "/Users/apple2015/Documents/Work/Bolsover District Council/Project/.venv/lib/python3.11/site-packages/urllib3/connection.py", line 516, in getresponse
    httplib_response = super().getresponse()
                       ^^^^^^^^^^^^^^^^^^^^^
  File "/Library/Frameworks/Python.framework/Versions/3.11/lib/python3.11/http/client.py", line 1378, in getresponse
    response.begin()
  File "/Library/Frameworks/Python.framework/Versions/3.11/lib/python3.11/http/client.py", line 318, in begin
    version, status, reason = self._read_status()
                              ^^^^^^^^^^^^^^^^^^^
  File "/Library/Frameworks/Python.framework/Versions/3.11/lib/python3.11/http/client.py", line 279, in _read_status
    line = str(self.fp.readline(_MAXLINE + 1), "iso-8859-1")
               ^^^^^^^^^^^^^^^^^^^^^^^^^^^^^^
  File "/Library/Frameworks/Python.framework/Versions/3.11/lib/python3.11/socket.py", line 706, in readinto
    return self._sock.recv_into(b)
           ^^^^^^^^^^^^^^^^^^^^^^^
  File "/Library/Frameworks/Python.framework/Versions/3.11/lib/python3.11/ssl.py", line 1278, in recv_into
    return self.read(nbytes, buffer)
           ^^^^^^^^^^^^^^^^^^^^^^^^^
  File "/Library/Frameworks/Python.framework/Versions/3.11/lib/python3.11/ssl.py", line 1134, in read
    return self._sslobj.read(len, buffer)
           ^^^^^^^^^^^^^^^^^^^^^^^^^^^^^^
TimeoutError: The read operation timed out

The above exception was the direct cause of the following exception:

Traceback (most recent call last):
  File "/Users/apple2015/Documents/Work/Bolsover District Council/Project/.venv/lib/python3.11/site-packages/urllib3/connectionpool.py", line 787, in urlopen
    response = self._make_request(
               ^^^^^^^^^^^^^^^^^^^
  File "/Users/apple2015/Documents/Work/Bolsover District Council/Project/.venv/lib/python3.11/site-packages/urllib3/connectionpool.py", line 536, in _make_request
    self._raise_timeout(err=e, url=url, timeout_value=read_timeout)
  File "/Users/apple2015/Documents/Work/Bolsover District Council/Project/.venv/lib/python3.11/site-packages/urllib3/connectionpool.py", line 367, in _raise_timeout
    raise ReadTimeoutError(
urllib3.exceptions.ReadTimeoutError: HTTPSConnectionPool(host='nominatim.openstreetmap.org', port=443): Read timed out. (read timeout=1)

The above exception was the direct cause of the following exception:

Traceback (most recent call last):
  File "/Users/apple2015/Documents/Work/Bolsover District Council/Project/.venv/lib/python3.11/site-packages/requests/adapters.py", line 667, in send
    resp = conn.urlopen(
           ^^^^^^^^^^^^^
  File "/Users/apple2015/Documents/Work/Bolsover District Council/Project/.venv/lib/python3.11/site-packages/urllib3/connectionpool.py", line 871, in urlopen
    return self.urlopen(
           ^^^^^^^^^^^^^
  File "/Users/apple2015/Documents/Work/Bolsover District Council/Project/.venv/lib/python3.11/site-packages/urllib3/connectionpool.py", line 871, in urlopen
    return self.urlopen(
           ^^^^^^^^^^^^^
  File "/Users/apple2015/Documents/Work/Bolsover District Council/Project/.venv/lib/python3.11/site-packages/urllib3/connectionpool.py", line 841, in urlopen
    retries = retries.increment(
              ^^^^^^^^^^^^^^^^^^
  File "/Users/apple2015/Documents/Work/Bolsover District Council/Project/.venv/lib/python3.11/site-packages/urllib3/util/retry.py", line 519, in increment
    raise MaxRetryError(_pool, url, reason) from reason  # type: ignore[arg-type]
    ^^^^^^^^^^^^^^^^^^^^^^^^^^^^^^^^^^^^^^^^^^^^^^^^^^^
urllib3.exceptions.MaxRetryError: HTTPSConnectionPool(host='nominatim.openstreetmap.org', port=443): Max retries exceeded with url: /search?q=S44+4RJ%2C+Bolsover+District%2C+UK&format=json&limit=1 (Caused by ReadTimeoutError("HTTPSConnectionPool(host='nominatim.openstreetmap.org', port=443): Read timed out. (read timeout=1)"))

During handling of the above exception, another exception occurred:

Traceback (most recent call last):
  File "/Users/apple2015/Documents/Work/Bolsover District Council/Project/.venv/lib/python3.11/site-packages/geopy/adapters.py", line 482, in _request
    resp = self.session.get(url, timeout=timeout, headers=headers)
           ^^^^^^^^^^^^^^^^^^^^^^^^^^^^^^^^^^^^^^^^^^^^^^^^^^^^^^^
  File "/Users/apple2015/Documents/Work/Bolsover District Council/Project/.venv/lib/python3.11/site-packages/requests/sessions.py", line 602, in get
    return self.request("GET", url, **kwargs)
           ^^^^^^^^^^^^^^^^^^^^^^^^^^^^^^^^^^
  File "/Users/apple2015/Documents/Work/Bolsover District Council/Project/.venv/lib/python3.11/site-packages/requests/sessions.py", line 589, in request
    resp = self.send(prep, **send_kwargs)
           ^^^^^^^^^^^^^^^^^^^^^^^^^^^^^^
  File "/Users/apple2015/Documents/Work/Bolsover District Council/Project/.venv/lib/python3.11/site-packages/requests/sessions.py", line 703, in send
    r = adapter.send(request, **kwargs)
        ^^^^^^^^^^^^^^^^^^^^^^^^^^^^^^^
  File "/Users/apple2015/Documents/Work/Bolsover District Council/Project/.venv/lib/python3.11/site-packages/requests/adapters.py", line 700, in send
    raise ConnectionError(e, request=request)
requests.exceptions.ConnectionError: HTTPSConnectionPool(host='nominatim.openstreetmap.org', port=443): Max retries exceeded with url: /search?q=S44+4RJ%2C+Bolsover+District%2C+UK&format=json&limit=1 (Caused by ReadTimeoutError("HTTPSConnectionPool(host='nominatim.openstreetmap.org', port=443): Read timed out. (read timeout=1)"))

During handling of the above exception, another exception occurred:

Traceback (most recent call last):
  File "/Users/apple2015/Documents/Work/Bolsover District Council/Project/processing/geocoding.py", line 94, in geocode_location
    location = geolocator.geocode(f"{location_name}, Bolsover District, UK", exactly_one=True)
               ^^^^^^^^^^^^^^^^^^^^^^^^^^^^^^^^^^^^^^^^^^^^^^^^^^^^^^^^^^^^^^^^^^^^^^^^^^^^^^^
  File "/Users/apple2015/Documents/Work/Bolsover District Council/Project/.venv/lib/python3.11/site-packages/geopy/geocoders/nominatim.py", line 297, in geocode
    return self._call_geocoder(url, callback, timeout=timeout)
           ^^^^^^^^^^^^^^^^^^^^^^^^^^^^^^^^^^^^^^^^^^^^^^^^^^^
  File "/Users/apple2015/Documents/Work/Bolsover District Council/Project/.venv/lib/python3.11/site-packages/geopy/geocoders/base.py", line 368, in _call_geocoder
    result = self.adapter.get_json(url, timeout=timeout, headers=req_headers)
             ^^^^^^^^^^^^^^^^^^^^^^^^^^^^^^^^^^^^^^^^^^^^^^^^^^^^^^^^^^^^^^^^
  File "/Users/apple2015/Documents/Work/Bolsover District Council/Project/.venv/lib/python3.11/site-packages/geopy/adapters.py", line 472, in get_json
    resp = self._request(url, timeout=timeout, headers=headers)
           ^^^^^^^^^^^^^^^^^^^^^^^^^^^^^^^^^^^^^^^^^^^^^^^^^^^^
  File "/Users/apple2015/Documents/Work/Bolsover District Council/Project/.venv/lib/python3.11/site-packages/geopy/adapters.py", line 494, in _request
    raise GeocoderUnavailable(message)
geopy.exc.GeocoderUnavailable: HTTPSConnectionPool(host='nominatim.openstreetmap.org', port=443): Max retries exceeded with url: /search?q=S44+4RJ%2C+Bolsover+District%2C+UK&format=json&limit=1 (Caused by ReadTimeoutError("HTTPSConnectionPool(host='nominatim.openstreetmap.org', port=443): Read timed out. (read timeout=1)"))
2025-04-07 00:18:12,875 - urllib3.connectionpool - WARNING - Retrying (Retry(total=1, connect=None, read=None, redirect=None, status=None)) after connection broken by 'ReadTimeoutError("HTTPSConnectionPool(host='nominatim.openstreetmap.org', port=443): Read timed out. (read timeout=1)")': /search?q=35+Birch+Road%2C+Bolsover%2C+S44+8UV%2C+Bolsover+District%2C+UK&format=json&limit=1
2025-04-07 00:18:13,934 - urllib3.connectionpool - WARNING - Retrying (Retry(total=0, connect=None, read=None, redirect=None, status=None)) after connection broken by 'ReadTimeoutError("HTTPSConnectionPool(host='nominatim.openstreetmap.org', port=443): Read timed out. (read timeout=1)")': /search?q=35+Birch+Road%2C+Bolsover%2C+S44+8UV%2C+Bolsover+District%2C+UK&format=json&limit=1
2025-04-07 00:18:15,004 - processing.geocoding - ERROR - Address geocoding error: HTTPSConnectionPool(host='nominatim.openstreetmap.org', port=443): Max retries exceeded with url: /search?q=35+Birch+Road%2C+Bolsover%2C+S44+8UV%2C+Bolsover+District%2C+UK&format=json&limit=1 (Caused by ReadTimeoutError("HTTPSConnectionPool(host='nominatim.openstreetmap.org', port=443): Read timed out. (read timeout=1)"))
Traceback (most recent call last):
  File "/Users/apple2015/Documents/Work/Bolsover District Council/Project/.venv/lib/python3.11/site-packages/urllib3/connectionpool.py", line 534, in _make_request
    response = conn.getresponse()
               ^^^^^^^^^^^^^^^^^^
  File "/Users/apple2015/Documents/Work/Bolsover District Council/Project/.venv/lib/python3.11/site-packages/urllib3/connection.py", line 516, in getresponse
    httplib_response = super().getresponse()
                       ^^^^^^^^^^^^^^^^^^^^^
  File "/Library/Frameworks/Python.framework/Versions/3.11/lib/python3.11/http/client.py", line 1378, in getresponse
    response.begin()
  File "/Library/Frameworks/Python.framework/Versions/3.11/lib/python3.11/http/client.py", line 318, in begin
    version, status, reason = self._read_status()
                              ^^^^^^^^^^^^^^^^^^^
  File "/Library/Frameworks/Python.framework/Versions/3.11/lib/python3.11/http/client.py", line 279, in _read_status
    line = str(self.fp.readline(_MAXLINE + 1), "iso-8859-1")
               ^^^^^^^^^^^^^^^^^^^^^^^^^^^^^^
  File "/Library/Frameworks/Python.framework/Versions/3.11/lib/python3.11/socket.py", line 706, in readinto
    return self._sock.recv_into(b)
           ^^^^^^^^^^^^^^^^^^^^^^^
  File "/Library/Frameworks/Python.framework/Versions/3.11/lib/python3.11/ssl.py", line 1278, in recv_into
    return self.read(nbytes, buffer)
           ^^^^^^^^^^^^^^^^^^^^^^^^^
  File "/Library/Frameworks/Python.framework/Versions/3.11/lib/python3.11/ssl.py", line 1134, in read
    return self._sslobj.read(len, buffer)
           ^^^^^^^^^^^^^^^^^^^^^^^^^^^^^^
TimeoutError: The read operation timed out

The above exception was the direct cause of the following exception:

Traceback (most recent call last):
  File "/Users/apple2015/Documents/Work/Bolsover District Council/Project/.venv/lib/python3.11/site-packages/urllib3/connectionpool.py", line 787, in urlopen
    response = self._make_request(
               ^^^^^^^^^^^^^^^^^^^
  File "/Users/apple2015/Documents/Work/Bolsover District Council/Project/.venv/lib/python3.11/site-packages/urllib3/connectionpool.py", line 536, in _make_request
    self._raise_timeout(err=e, url=url, timeout_value=read_timeout)
  File "/Users/apple2015/Documents/Work/Bolsover District Council/Project/.venv/lib/python3.11/site-packages/urllib3/connectionpool.py", line 367, in _raise_timeout
    raise ReadTimeoutError(
urllib3.exceptions.ReadTimeoutError: HTTPSConnectionPool(host='nominatim.openstreetmap.org', port=443): Read timed out. (read timeout=1)

The above exception was the direct cause of the following exception:

Traceback (most recent call last):
  File "/Users/apple2015/Documents/Work/Bolsover District Council/Project/.venv/lib/python3.11/site-packages/requests/adapters.py", line 667, in send
    resp = conn.urlopen(
           ^^^^^^^^^^^^^
  File "/Users/apple2015/Documents/Work/Bolsover District Council/Project/.venv/lib/python3.11/site-packages/urllib3/connectionpool.py", line 871, in urlopen
    return self.urlopen(
           ^^^^^^^^^^^^^
  File "/Users/apple2015/Documents/Work/Bolsover District Council/Project/.venv/lib/python3.11/site-packages/urllib3/connectionpool.py", line 871, in urlopen
    return self.urlopen(
           ^^^^^^^^^^^^^
  File "/Users/apple2015/Documents/Work/Bolsover District Council/Project/.venv/lib/python3.11/site-packages/urllib3/connectionpool.py", line 841, in urlopen
    retries = retries.increment(
              ^^^^^^^^^^^^^^^^^^
  File "/Users/apple2015/Documents/Work/Bolsover District Council/Project/.venv/lib/python3.11/site-packages/urllib3/util/retry.py", line 519, in increment
    raise MaxRetryError(_pool, url, reason) from reason  # type: ignore[arg-type]
    ^^^^^^^^^^^^^^^^^^^^^^^^^^^^^^^^^^^^^^^^^^^^^^^^^^^
urllib3.exceptions.MaxRetryError: HTTPSConnectionPool(host='nominatim.openstreetmap.org', port=443): Max retries exceeded with url: /search?q=35+Birch+Road%2C+Bolsover%2C+S44+8UV%2C+Bolsover+District%2C+UK&format=json&limit=1 (Caused by ReadTimeoutError("HTTPSConnectionPool(host='nominatim.openstreetmap.org', port=443): Read timed out. (read timeout=1)"))

During handling of the above exception, another exception occurred:

Traceback (most recent call last):
  File "/Users/apple2015/Documents/Work/Bolsover District Council/Project/.venv/lib/python3.11/site-packages/geopy/adapters.py", line 482, in _request
    resp = self.session.get(url, timeout=timeout, headers=headers)
           ^^^^^^^^^^^^^^^^^^^^^^^^^^^^^^^^^^^^^^^^^^^^^^^^^^^^^^^
  File "/Users/apple2015/Documents/Work/Bolsover District Council/Project/.venv/lib/python3.11/site-packages/requests/sessions.py", line 602, in get
    return self.request("GET", url, **kwargs)
           ^^^^^^^^^^^^^^^^^^^^^^^^^^^^^^^^^^
  File "/Users/apple2015/Documents/Work/Bolsover District Council/Project/.venv/lib/python3.11/site-packages/requests/sessions.py", line 589, in request
    resp = self.send(prep, **send_kwargs)
           ^^^^^^^^^^^^^^^^^^^^^^^^^^^^^^
  File "/Users/apple2015/Documents/Work/Bolsover District Council/Project/.venv/lib/python3.11/site-packages/requests/sessions.py", line 703, in send
    r = adapter.send(request, **kwargs)
        ^^^^^^^^^^^^^^^^^^^^^^^^^^^^^^^
  File "/Users/apple2015/Documents/Work/Bolsover District Council/Project/.venv/lib/python3.11/site-packages/requests/adapters.py", line 700, in send
    raise ConnectionError(e, request=request)
requests.exceptions.ConnectionError: HTTPSConnectionPool(host='nominatim.openstreetmap.org', port=443): Max retries exceeded with url: /search?q=35+Birch+Road%2C+Bolsover%2C+S44+8UV%2C+Bolsover+District%2C+UK&format=json&limit=1 (Caused by ReadTimeoutError("HTTPSConnectionPool(host='nominatim.openstreetmap.org', port=443): Read timed out. (read timeout=1)"))

During handling of the above exception, another exception occurred:

Traceback (most recent call last):
  File "/Users/apple2015/Documents/Work/Bolsover District Council/Project/processing/geocoding.py", line 94, in geocode_location
    location = geolocator.geocode(f"{location_name}, Bolsover District, UK", exactly_one=True)
               ^^^^^^^^^^^^^^^^^^^^^^^^^^^^^^^^^^^^^^^^^^^^^^^^^^^^^^^^^^^^^^^^^^^^^^^^^^^^^^^
  File "/Users/apple2015/Documents/Work/Bolsover District Council/Project/.venv/lib/python3.11/site-packages/geopy/geocoders/nominatim.py", line 297, in geocode
    return self._call_geocoder(url, callback, timeout=timeout)
           ^^^^^^^^^^^^^^^^^^^^^^^^^^^^^^^^^^^^^^^^^^^^^^^^^^^
  File "/Users/apple2015/Documents/Work/Bolsover District Council/Project/.venv/lib/python3.11/site-packages/geopy/geocoders/base.py", line 368, in _call_geocoder
    result = self.adapter.get_json(url, timeout=timeout, headers=req_headers)
             ^^^^^^^^^^^^^^^^^^^^^^^^^^^^^^^^^^^^^^^^^^^^^^^^^^^^^^^^^^^^^^^^
  File "/Users/apple2015/Documents/Work/Bolsover District Council/Project/.venv/lib/python3.11/site-packages/geopy/adapters.py", line 472, in get_json
    resp = self._request(url, timeout=timeout, headers=headers)
           ^^^^^^^^^^^^^^^^^^^^^^^^^^^^^^^^^^^^^^^^^^^^^^^^^^^^
  File "/Users/apple2015/Documents/Work/Bolsover District Council/Project/.venv/lib/python3.11/site-packages/geopy/adapters.py", line 494, in _request
    raise GeocoderUnavailable(message)
geopy.exc.GeocoderUnavailable: HTTPSConnectionPool(host='nominatim.openstreetmap.org', port=443): Max retries exceeded with url: /search?q=35+Birch+Road%2C+Bolsover%2C+S44+8UV%2C+Bolsover+District%2C+UK&format=json&limit=1 (Caused by ReadTimeoutError("HTTPSConnectionPool(host='nominatim.openstreetmap.org', port=443): Read timed out. (read timeout=1)"))
2025-04-07 00:18:18,877 - urllib3.connectionpool - WARNING - Retrying (Retry(total=1, connect=None, read=None, redirect=None, status=None)) after connection broken by 'ReadTimeoutError("HTTPSConnectionPool(host='nominatim.openstreetmap.org', port=443): Read timed out. (read timeout=1)")': /search?q=S44+3DE&format=json&limit=1
2025-04-07 00:18:22,806 - urllib3.connectionpool - WARNING - Retrying (Retry(total=1, connect=None, read=None, redirect=None, status=None)) after connection broken by 'ReadTimeoutError("HTTPSConnectionPool(host='nominatim.openstreetmap.org', port=443): Read timed out. (read timeout=1)")': /search?q=64+Willow+Lane%2C+Bolsover%2C+S44+5FG%2C+Bolsover+District%2C+UK&format=json&limit=1
2025-04-07 00:18:23,870 - urllib3.connectionpool - WARNING - Retrying (Retry(total=0, connect=None, read=None, redirect=None, status=None)) after connection broken by 'ReadTimeoutError("HTTPSConnectionPool(host='nominatim.openstreetmap.org', port=443): Read timed out. (read timeout=1)")': /search?q=64+Willow+Lane%2C+Bolsover%2C+S44+5FG%2C+Bolsover+District%2C+UK&format=json&limit=1
2025-04-07 00:18:24,928 - processing.geocoding - ERROR - Address geocoding error: HTTPSConnectionPool(host='nominatim.openstreetmap.org', port=443): Max retries exceeded with url: /search?q=64+Willow+Lane%2C+Bolsover%2C+S44+5FG%2C+Bolsover+District%2C+UK&format=json&limit=1 (Caused by ReadTimeoutError("HTTPSConnectionPool(host='nominatim.openstreetmap.org', port=443): Read timed out. (read timeout=1)"))
Traceback (most recent call last):
  File "/Users/apple2015/Documents/Work/Bolsover District Council/Project/.venv/lib/python3.11/site-packages/urllib3/connectionpool.py", line 534, in _make_request
    response = conn.getresponse()
               ^^^^^^^^^^^^^^^^^^
  File "/Users/apple2015/Documents/Work/Bolsover District Council/Project/.venv/lib/python3.11/site-packages/urllib3/connection.py", line 516, in getresponse
    httplib_response = super().getresponse()
                       ^^^^^^^^^^^^^^^^^^^^^
  File "/Library/Frameworks/Python.framework/Versions/3.11/lib/python3.11/http/client.py", line 1378, in getresponse
    response.begin()
  File "/Library/Frameworks/Python.framework/Versions/3.11/lib/python3.11/http/client.py", line 318, in begin
    version, status, reason = self._read_status()
                              ^^^^^^^^^^^^^^^^^^^
  File "/Library/Frameworks/Python.framework/Versions/3.11/lib/python3.11/http/client.py", line 279, in _read_status
    line = str(self.fp.readline(_MAXLINE + 1), "iso-8859-1")
               ^^^^^^^^^^^^^^^^^^^^^^^^^^^^^^
  File "/Library/Frameworks/Python.framework/Versions/3.11/lib/python3.11/socket.py", line 706, in readinto
    return self._sock.recv_into(b)
           ^^^^^^^^^^^^^^^^^^^^^^^
  File "/Library/Frameworks/Python.framework/Versions/3.11/lib/python3.11/ssl.py", line 1278, in recv_into
    return self.read(nbytes, buffer)
           ^^^^^^^^^^^^^^^^^^^^^^^^^
  File "/Library/Frameworks/Python.framework/Versions/3.11/lib/python3.11/ssl.py", line 1134, in read
    return self._sslobj.read(len, buffer)
           ^^^^^^^^^^^^^^^^^^^^^^^^^^^^^^
TimeoutError: The read operation timed out

The above exception was the direct cause of the following exception:

Traceback (most recent call last):
  File "/Users/apple2015/Documents/Work/Bolsover District Council/Project/.venv/lib/python3.11/site-packages/urllib3/connectionpool.py", line 787, in urlopen
    response = self._make_request(
               ^^^^^^^^^^^^^^^^^^^
  File "/Users/apple2015/Documents/Work/Bolsover District Council/Project/.venv/lib/python3.11/site-packages/urllib3/connectionpool.py", line 536, in _make_request
    self._raise_timeout(err=e, url=url, timeout_value=read_timeout)
  File "/Users/apple2015/Documents/Work/Bolsover District Council/Project/.venv/lib/python3.11/site-packages/urllib3/connectionpool.py", line 367, in _raise_timeout
    raise ReadTimeoutError(
urllib3.exceptions.ReadTimeoutError: HTTPSConnectionPool(host='nominatim.openstreetmap.org', port=443): Read timed out. (read timeout=1)

The above exception was the direct cause of the following exception:

Traceback (most recent call last):
  File "/Users/apple2015/Documents/Work/Bolsover District Council/Project/.venv/lib/python3.11/site-packages/requests/adapters.py", line 667, in send
    resp = conn.urlopen(
           ^^^^^^^^^^^^^
  File "/Users/apple2015/Documents/Work/Bolsover District Council/Project/.venv/lib/python3.11/site-packages/urllib3/connectionpool.py", line 871, in urlopen
    return self.urlopen(
           ^^^^^^^^^^^^^
  File "/Users/apple2015/Documents/Work/Bolsover District Council/Project/.venv/lib/python3.11/site-packages/urllib3/connectionpool.py", line 871, in urlopen
    return self.urlopen(
           ^^^^^^^^^^^^^
  File "/Users/apple2015/Documents/Work/Bolsover District Council/Project/.venv/lib/python3.11/site-packages/urllib3/connectionpool.py", line 841, in urlopen
    retries = retries.increment(
              ^^^^^^^^^^^^^^^^^^
  File "/Users/apple2015/Documents/Work/Bolsover District Council/Project/.venv/lib/python3.11/site-packages/urllib3/util/retry.py", line 519, in increment
    raise MaxRetryError(_pool, url, reason) from reason  # type: ignore[arg-type]
    ^^^^^^^^^^^^^^^^^^^^^^^^^^^^^^^^^^^^^^^^^^^^^^^^^^^
urllib3.exceptions.MaxRetryError: HTTPSConnectionPool(host='nominatim.openstreetmap.org', port=443): Max retries exceeded with url: /search?q=64+Willow+Lane%2C+Bolsover%2C+S44+5FG%2C+Bolsover+District%2C+UK&format=json&limit=1 (Caused by ReadTimeoutError("HTTPSConnectionPool(host='nominatim.openstreetmap.org', port=443): Read timed out. (read timeout=1)"))

During handling of the above exception, another exception occurred:

Traceback (most recent call last):
  File "/Users/apple2015/Documents/Work/Bolsover District Council/Project/.venv/lib/python3.11/site-packages/geopy/adapters.py", line 482, in _request
    resp = self.session.get(url, timeout=timeout, headers=headers)
           ^^^^^^^^^^^^^^^^^^^^^^^^^^^^^^^^^^^^^^^^^^^^^^^^^^^^^^^
  File "/Users/apple2015/Documents/Work/Bolsover District Council/Project/.venv/lib/python3.11/site-packages/requests/sessions.py", line 602, in get
    return self.request("GET", url, **kwargs)
           ^^^^^^^^^^^^^^^^^^^^^^^^^^^^^^^^^^
  File "/Users/apple2015/Documents/Work/Bolsover District Council/Project/.venv/lib/python3.11/site-packages/requests/sessions.py", line 589, in request
    resp = self.send(prep, **send_kwargs)
           ^^^^^^^^^^^^^^^^^^^^^^^^^^^^^^
  File "/Users/apple2015/Documents/Work/Bolsover District Council/Project/.venv/lib/python3.11/site-packages/requests/sessions.py", line 703, in send
    r = adapter.send(request, **kwargs)
        ^^^^^^^^^^^^^^^^^^^^^^^^^^^^^^^
  File "/Users/apple2015/Documents/Work/Bolsover District Council/Project/.venv/lib/python3.11/site-packages/requests/adapters.py", line 700, in send
    raise ConnectionError(e, request=request)
requests.exceptions.ConnectionError: HTTPSConnectionPool(host='nominatim.openstreetmap.org', port=443): Max retries exceeded with url: /search?q=64+Willow+Lane%2C+Bolsover%2C+S44+5FG%2C+Bolsover+District%2C+UK&format=json&limit=1 (Caused by ReadTimeoutError("HTTPSConnectionPool(host='nominatim.openstreetmap.org', port=443): Read timed out. (read timeout=1)"))

During handling of the above exception, another exception occurred:

Traceback (most recent call last):
  File "/Users/apple2015/Documents/Work/Bolsover District Council/Project/processing/geocoding.py", line 94, in geocode_location
    location = geolocator.geocode(f"{location_name}, Bolsover District, UK", exactly_one=True)
               ^^^^^^^^^^^^^^^^^^^^^^^^^^^^^^^^^^^^^^^^^^^^^^^^^^^^^^^^^^^^^^^^^^^^^^^^^^^^^^^
  File "/Users/apple2015/Documents/Work/Bolsover District Council/Project/.venv/lib/python3.11/site-packages/geopy/geocoders/nominatim.py", line 297, in geocode
    return self._call_geocoder(url, callback, timeout=timeout)
           ^^^^^^^^^^^^^^^^^^^^^^^^^^^^^^^^^^^^^^^^^^^^^^^^^^^
  File "/Users/apple2015/Documents/Work/Bolsover District Council/Project/.venv/lib/python3.11/site-packages/geopy/geocoders/base.py", line 368, in _call_geocoder
    result = self.adapter.get_json(url, timeout=timeout, headers=req_headers)
             ^^^^^^^^^^^^^^^^^^^^^^^^^^^^^^^^^^^^^^^^^^^^^^^^^^^^^^^^^^^^^^^^
  File "/Users/apple2015/Documents/Work/Bolsover District Council/Project/.venv/lib/python3.11/site-packages/geopy/adapters.py", line 472, in get_json
    resp = self._request(url, timeout=timeout, headers=headers)
           ^^^^^^^^^^^^^^^^^^^^^^^^^^^^^^^^^^^^^^^^^^^^^^^^^^^^
  File "/Users/apple2015/Documents/Work/Bolsover District Council/Project/.venv/lib/python3.11/site-packages/geopy/adapters.py", line 494, in _request
    raise GeocoderUnavailable(message)
geopy.exc.GeocoderUnavailable: HTTPSConnectionPool(host='nominatim.openstreetmap.org', port=443): Max retries exceeded with url: /search?q=64+Willow+Lane%2C+Bolsover%2C+S44+5FG%2C+Bolsover+District%2C+UK&format=json&limit=1 (Caused by ReadTimeoutError("HTTPSConnectionPool(host='nominatim.openstreetmap.org', port=443): Read timed out. (read timeout=1)"))
2025-04-07 00:18:27,830 - urllib3.connectionpool - WARNING - Retrying (Retry(total=1, connect=None, read=None, redirect=None, status=None)) after connection broken by 'ReadTimeoutError("HTTPSConnectionPool(host='nominatim.openstreetmap.org', port=443): Read timed out. (read timeout=1)")': /search?q=S44+8UV%2C+Bolsover+District%2C+UK&format=json&limit=1
2025-04-07 00:18:31,820 - urllib3.connectionpool - WARNING - Retrying (Retry(total=1, connect=None, read=None, redirect=None, status=None)) after connection broken by 'ReadTimeoutError("HTTPSConnectionPool(host='nominatim.openstreetmap.org', port=443): Read timed out. (read timeout=1)")': /search?q=27+Market+Street%2C+Bolsover%2C+S44+4RJ%2C+Bolsover+District%2C+UK&format=json&limit=1
2025-04-07 00:18:32,899 - urllib3.connectionpool - WARNING - Retrying (Retry(total=0, connect=None, read=None, redirect=None, status=None)) after connection broken by 'ReadTimeoutError("HTTPSConnectionPool(host='nominatim.openstreetmap.org', port=443): Read timed out. (read timeout=1)")': /search?q=27+Market+Street%2C+Bolsover%2C+S44+4RJ%2C+Bolsover+District%2C+UK&format=json&limit=1
2025-04-07 00:18:34,057 - processing.geocoding - ERROR - Address geocoding error: HTTPSConnectionPool(host='nominatim.openstreetmap.org', port=443): Max retries exceeded with url: /search?q=27+Market+Street%2C+Bolsover%2C+S44+4RJ%2C+Bolsover+District%2C+UK&format=json&limit=1 (Caused by ReadTimeoutError("HTTPSConnectionPool(host='nominatim.openstreetmap.org', port=443): Read timed out. (read timeout=1)"))
Traceback (most recent call last):
  File "/Users/apple2015/Documents/Work/Bolsover District Council/Project/.venv/lib/python3.11/site-packages/urllib3/connectionpool.py", line 534, in _make_request
    response = conn.getresponse()
               ^^^^^^^^^^^^^^^^^^
  File "/Users/apple2015/Documents/Work/Bolsover District Council/Project/.venv/lib/python3.11/site-packages/urllib3/connection.py", line 516, in getresponse
    httplib_response = super().getresponse()
                       ^^^^^^^^^^^^^^^^^^^^^
  File "/Library/Frameworks/Python.framework/Versions/3.11/lib/python3.11/http/client.py", line 1378, in getresponse
    response.begin()
  File "/Library/Frameworks/Python.framework/Versions/3.11/lib/python3.11/http/client.py", line 318, in begin
    version, status, reason = self._read_status()
                              ^^^^^^^^^^^^^^^^^^^
  File "/Library/Frameworks/Python.framework/Versions/3.11/lib/python3.11/http/client.py", line 279, in _read_status
    line = str(self.fp.readline(_MAXLINE + 1), "iso-8859-1")
               ^^^^^^^^^^^^^^^^^^^^^^^^^^^^^^
  File "/Library/Frameworks/Python.framework/Versions/3.11/lib/python3.11/socket.py", line 706, in readinto
    return self._sock.recv_into(b)
           ^^^^^^^^^^^^^^^^^^^^^^^
  File "/Library/Frameworks/Python.framework/Versions/3.11/lib/python3.11/ssl.py", line 1278, in recv_into
    return self.read(nbytes, buffer)
           ^^^^^^^^^^^^^^^^^^^^^^^^^
  File "/Library/Frameworks/Python.framework/Versions/3.11/lib/python3.11/ssl.py", line 1134, in read
    return self._sslobj.read(len, buffer)
           ^^^^^^^^^^^^^^^^^^^^^^^^^^^^^^
TimeoutError: The read operation timed out

The above exception was the direct cause of the following exception:

Traceback (most recent call last):
  File "/Users/apple2015/Documents/Work/Bolsover District Council/Project/.venv/lib/python3.11/site-packages/urllib3/connectionpool.py", line 787, in urlopen
    response = self._make_request(
               ^^^^^^^^^^^^^^^^^^^
  File "/Users/apple2015/Documents/Work/Bolsover District Council/Project/.venv/lib/python3.11/site-packages/urllib3/connectionpool.py", line 536, in _make_request
    self._raise_timeout(err=e, url=url, timeout_value=read_timeout)
  File "/Users/apple2015/Documents/Work/Bolsover District Council/Project/.venv/lib/python3.11/site-packages/urllib3/connectionpool.py", line 367, in _raise_timeout
    raise ReadTimeoutError(
urllib3.exceptions.ReadTimeoutError: HTTPSConnectionPool(host='nominatim.openstreetmap.org', port=443): Read timed out. (read timeout=1)

The above exception was the direct cause of the following exception:

Traceback (most recent call last):
  File "/Users/apple2015/Documents/Work/Bolsover District Council/Project/.venv/lib/python3.11/site-packages/requests/adapters.py", line 667, in send
    resp = conn.urlopen(
           ^^^^^^^^^^^^^
  File "/Users/apple2015/Documents/Work/Bolsover District Council/Project/.venv/lib/python3.11/site-packages/urllib3/connectionpool.py", line 871, in urlopen
    return self.urlopen(
           ^^^^^^^^^^^^^
  File "/Users/apple2015/Documents/Work/Bolsover District Council/Project/.venv/lib/python3.11/site-packages/urllib3/connectionpool.py", line 871, in urlopen
    return self.urlopen(
           ^^^^^^^^^^^^^
  File "/Users/apple2015/Documents/Work/Bolsover District Council/Project/.venv/lib/python3.11/site-packages/urllib3/connectionpool.py", line 841, in urlopen
    retries = retries.increment(
              ^^^^^^^^^^^^^^^^^^
  File "/Users/apple2015/Documents/Work/Bolsover District Council/Project/.venv/lib/python3.11/site-packages/urllib3/util/retry.py", line 519, in increment
    raise MaxRetryError(_pool, url, reason) from reason  # type: ignore[arg-type]
    ^^^^^^^^^^^^^^^^^^^^^^^^^^^^^^^^^^^^^^^^^^^^^^^^^^^
urllib3.exceptions.MaxRetryError: HTTPSConnectionPool(host='nominatim.openstreetmap.org', port=443): Max retries exceeded with url: /search?q=27+Market+Street%2C+Bolsover%2C+S44+4RJ%2C+Bolsover+District%2C+UK&format=json&limit=1 (Caused by ReadTimeoutError("HTTPSConnectionPool(host='nominatim.openstreetmap.org', port=443): Read timed out. (read timeout=1)"))

During handling of the above exception, another exception occurred:

Traceback (most recent call last):
  File "/Users/apple2015/Documents/Work/Bolsover District Council/Project/.venv/lib/python3.11/site-packages/geopy/adapters.py", line 482, in _request
    resp = self.session.get(url, timeout=timeout, headers=headers)
           ^^^^^^^^^^^^^^^^^^^^^^^^^^^^^^^^^^^^^^^^^^^^^^^^^^^^^^^
  File "/Users/apple2015/Documents/Work/Bolsover District Council/Project/.venv/lib/python3.11/site-packages/requests/sessions.py", line 602, in get
    return self.request("GET", url, **kwargs)
           ^^^^^^^^^^^^^^^^^^^^^^^^^^^^^^^^^^
  File "/Users/apple2015/Documents/Work/Bolsover District Council/Project/.venv/lib/python3.11/site-packages/requests/sessions.py", line 589, in request
    resp = self.send(prep, **send_kwargs)
           ^^^^^^^^^^^^^^^^^^^^^^^^^^^^^^
  File "/Users/apple2015/Documents/Work/Bolsover District Council/Project/.venv/lib/python3.11/site-packages/requests/sessions.py", line 703, in send
    r = adapter.send(request, **kwargs)
        ^^^^^^^^^^^^^^^^^^^^^^^^^^^^^^^
  File "/Users/apple2015/Documents/Work/Bolsover District Council/Project/.venv/lib/python3.11/site-packages/requests/adapters.py", line 700, in send
    raise ConnectionError(e, request=request)
requests.exceptions.ConnectionError: HTTPSConnectionPool(host='nominatim.openstreetmap.org', port=443): Max retries exceeded with url: /search?q=27+Market+Street%2C+Bolsover%2C+S44+4RJ%2C+Bolsover+District%2C+UK&format=json&limit=1 (Caused by ReadTimeoutError("HTTPSConnectionPool(host='nominatim.openstreetmap.org', port=443): Read timed out. (read timeout=1)"))

During handling of the above exception, another exception occurred:

Traceback (most recent call last):
  File "/Users/apple2015/Documents/Work/Bolsover District Council/Project/processing/geocoding.py", line 94, in geocode_location
    location = geolocator.geocode(f"{location_name}, Bolsover District, UK", exactly_one=True)
               ^^^^^^^^^^^^^^^^^^^^^^^^^^^^^^^^^^^^^^^^^^^^^^^^^^^^^^^^^^^^^^^^^^^^^^^^^^^^^^^
  File "/Users/apple2015/Documents/Work/Bolsover District Council/Project/.venv/lib/python3.11/site-packages/geopy/geocoders/nominatim.py", line 297, in geocode
    return self._call_geocoder(url, callback, timeout=timeout)
           ^^^^^^^^^^^^^^^^^^^^^^^^^^^^^^^^^^^^^^^^^^^^^^^^^^^
  File "/Users/apple2015/Documents/Work/Bolsover District Council/Project/.venv/lib/python3.11/site-packages/geopy/geocoders/base.py", line 368, in _call_geocoder
    result = self.adapter.get_json(url, timeout=timeout, headers=req_headers)
             ^^^^^^^^^^^^^^^^^^^^^^^^^^^^^^^^^^^^^^^^^^^^^^^^^^^^^^^^^^^^^^^^
  File "/Users/apple2015/Documents/Work/Bolsover District Council/Project/.venv/lib/python3.11/site-packages/geopy/adapters.py", line 472, in get_json
    resp = self._request(url, timeout=timeout, headers=headers)
           ^^^^^^^^^^^^^^^^^^^^^^^^^^^^^^^^^^^^^^^^^^^^^^^^^^^^
  File "/Users/apple2015/Documents/Work/Bolsover District Council/Project/.venv/lib/python3.11/site-packages/geopy/adapters.py", line 494, in _request
    raise GeocoderUnavailable(message)
geopy.exc.GeocoderUnavailable: HTTPSConnectionPool(host='nominatim.openstreetmap.org', port=443): Max retries exceeded with url: /search?q=27+Market+Street%2C+Bolsover%2C+S44+4RJ%2C+Bolsover+District%2C+UK&format=json&limit=1 (Caused by ReadTimeoutError("HTTPSConnectionPool(host='nominatim.openstreetmap.org', port=443): Read timed out. (read timeout=1)"))
2025-04-07 00:18:35,834 - urllib3.connectionpool - WARNING - Retrying (Retry(total=1, connect=None, read=None, redirect=None, status=None)) after connection broken by 'ReadTimeoutError("HTTPSConnectionPool(host='nominatim.openstreetmap.org', port=443): Read timed out. (read timeout=1)")': /search?q=S44+8NB%2C+Bolsover+District%2C+UK&format=json&limit=1
2025-04-07 00:18:36,892 - urllib3.connectionpool - WARNING - Retrying (Retry(total=0, connect=None, read=None, redirect=None, status=None)) after connection broken by 'ReadTimeoutError("HTTPSConnectionPool(host='nominatim.openstreetmap.org', port=443): Read timed out. (read timeout=1)")': /search?q=S44+8NB%2C+Bolsover+District%2C+UK&format=json&limit=1
2025-04-07 00:18:37,968 - processing.geocoding - ERROR - Address geocoding error: HTTPSConnectionPool(host='nominatim.openstreetmap.org', port=443): Max retries exceeded with url: /search?q=S44+8NB%2C+Bolsover+District%2C+UK&format=json&limit=1 (Caused by ReadTimeoutError("HTTPSConnectionPool(host='nominatim.openstreetmap.org', port=443): Read timed out. (read timeout=1)"))
Traceback (most recent call last):
  File "/Users/apple2015/Documents/Work/Bolsover District Council/Project/.venv/lib/python3.11/site-packages/urllib3/connectionpool.py", line 534, in _make_request
    response = conn.getresponse()
               ^^^^^^^^^^^^^^^^^^
  File "/Users/apple2015/Documents/Work/Bolsover District Council/Project/.venv/lib/python3.11/site-packages/urllib3/connection.py", line 516, in getresponse
    httplib_response = super().getresponse()
                       ^^^^^^^^^^^^^^^^^^^^^
  File "/Library/Frameworks/Python.framework/Versions/3.11/lib/python3.11/http/client.py", line 1378, in getresponse
    response.begin()
  File "/Library/Frameworks/Python.framework/Versions/3.11/lib/python3.11/http/client.py", line 318, in begin
    version, status, reason = self._read_status()
                              ^^^^^^^^^^^^^^^^^^^
  File "/Library/Frameworks/Python.framework/Versions/3.11/lib/python3.11/http/client.py", line 279, in _read_status
    line = str(self.fp.readline(_MAXLINE + 1), "iso-8859-1")
               ^^^^^^^^^^^^^^^^^^^^^^^^^^^^^^
  File "/Library/Frameworks/Python.framework/Versions/3.11/lib/python3.11/socket.py", line 706, in readinto
    return self._sock.recv_into(b)
           ^^^^^^^^^^^^^^^^^^^^^^^
  File "/Library/Frameworks/Python.framework/Versions/3.11/lib/python3.11/ssl.py", line 1278, in recv_into
    return self.read(nbytes, buffer)
           ^^^^^^^^^^^^^^^^^^^^^^^^^
  File "/Library/Frameworks/Python.framework/Versions/3.11/lib/python3.11/ssl.py", line 1134, in read
    return self._sslobj.read(len, buffer)
           ^^^^^^^^^^^^^^^^^^^^^^^^^^^^^^
TimeoutError: The read operation timed out

The above exception was the direct cause of the following exception:

Traceback (most recent call last):
  File "/Users/apple2015/Documents/Work/Bolsover District Council/Project/.venv/lib/python3.11/site-packages/urllib3/connectionpool.py", line 787, in urlopen
    response = self._make_request(
               ^^^^^^^^^^^^^^^^^^^
  File "/Users/apple2015/Documents/Work/Bolsover District Council/Project/.venv/lib/python3.11/site-packages/urllib3/connectionpool.py", line 536, in _make_request
    self._raise_timeout(err=e, url=url, timeout_value=read_timeout)
  File "/Users/apple2015/Documents/Work/Bolsover District Council/Project/.venv/lib/python3.11/site-packages/urllib3/connectionpool.py", line 367, in _raise_timeout
    raise ReadTimeoutError(
urllib3.exceptions.ReadTimeoutError: HTTPSConnectionPool(host='nominatim.openstreetmap.org', port=443): Read timed out. (read timeout=1)

The above exception was the direct cause of the following exception:

Traceback (most recent call last):
  File "/Users/apple2015/Documents/Work/Bolsover District Council/Project/.venv/lib/python3.11/site-packages/requests/adapters.py", line 667, in send
    resp = conn.urlopen(
           ^^^^^^^^^^^^^
  File "/Users/apple2015/Documents/Work/Bolsover District Council/Project/.venv/lib/python3.11/site-packages/urllib3/connectionpool.py", line 871, in urlopen
    return self.urlopen(
           ^^^^^^^^^^^^^
  File "/Users/apple2015/Documents/Work/Bolsover District Council/Project/.venv/lib/python3.11/site-packages/urllib3/connectionpool.py", line 871, in urlopen
    return self.urlopen(
           ^^^^^^^^^^^^^
  File "/Users/apple2015/Documents/Work/Bolsover District Council/Project/.venv/lib/python3.11/site-packages/urllib3/connectionpool.py", line 841, in urlopen
    retries = retries.increment(
              ^^^^^^^^^^^^^^^^^^
  File "/Users/apple2015/Documents/Work/Bolsover District Council/Project/.venv/lib/python3.11/site-packages/urllib3/util/retry.py", line 519, in increment
    raise MaxRetryError(_pool, url, reason) from reason  # type: ignore[arg-type]
    ^^^^^^^^^^^^^^^^^^^^^^^^^^^^^^^^^^^^^^^^^^^^^^^^^^^
urllib3.exceptions.MaxRetryError: HTTPSConnectionPool(host='nominatim.openstreetmap.org', port=443): Max retries exceeded with url: /search?q=S44+8NB%2C+Bolsover+District%2C+UK&format=json&limit=1 (Caused by ReadTimeoutError("HTTPSConnectionPool(host='nominatim.openstreetmap.org', port=443): Read timed out. (read timeout=1)"))

During handling of the above exception, another exception occurred:

Traceback (most recent call last):
  File "/Users/apple2015/Documents/Work/Bolsover District Council/Project/.venv/lib/python3.11/site-packages/geopy/adapters.py", line 482, in _request
    resp = self.session.get(url, timeout=timeout, headers=headers)
           ^^^^^^^^^^^^^^^^^^^^^^^^^^^^^^^^^^^^^^^^^^^^^^^^^^^^^^^
  File "/Users/apple2015/Documents/Work/Bolsover District Council/Project/.venv/lib/python3.11/site-packages/requests/sessions.py", line 602, in get
    return self.request("GET", url, **kwargs)
           ^^^^^^^^^^^^^^^^^^^^^^^^^^^^^^^^^^
  File "/Users/apple2015/Documents/Work/Bolsover District Council/Project/.venv/lib/python3.11/site-packages/requests/sessions.py", line 589, in request
    resp = self.send(prep, **send_kwargs)
           ^^^^^^^^^^^^^^^^^^^^^^^^^^^^^^
  File "/Users/apple2015/Documents/Work/Bolsover District Council/Project/.venv/lib/python3.11/site-packages/requests/sessions.py", line 703, in send
    r = adapter.send(request, **kwargs)
        ^^^^^^^^^^^^^^^^^^^^^^^^^^^^^^^
  File "/Users/apple2015/Documents/Work/Bolsover District Council/Project/.venv/lib/python3.11/site-packages/requests/adapters.py", line 700, in send
    raise ConnectionError(e, request=request)
requests.exceptions.ConnectionError: HTTPSConnectionPool(host='nominatim.openstreetmap.org', port=443): Max retries exceeded with url: /search?q=S44+8NB%2C+Bolsover+District%2C+UK&format=json&limit=1 (Caused by ReadTimeoutError("HTTPSConnectionPool(host='nominatim.openstreetmap.org', port=443): Read timed out. (read timeout=1)"))

During handling of the above exception, another exception occurred:

Traceback (most recent call last):
  File "/Users/apple2015/Documents/Work/Bolsover District Council/Project/processing/geocoding.py", line 94, in geocode_location
    location = geolocator.geocode(f"{location_name}, Bolsover District, UK", exactly_one=True)
               ^^^^^^^^^^^^^^^^^^^^^^^^^^^^^^^^^^^^^^^^^^^^^^^^^^^^^^^^^^^^^^^^^^^^^^^^^^^^^^^
  File "/Users/apple2015/Documents/Work/Bolsover District Council/Project/.venv/lib/python3.11/site-packages/geopy/geocoders/nominatim.py", line 297, in geocode
    return self._call_geocoder(url, callback, timeout=timeout)
           ^^^^^^^^^^^^^^^^^^^^^^^^^^^^^^^^^^^^^^^^^^^^^^^^^^^
  File "/Users/apple2015/Documents/Work/Bolsover District Council/Project/.venv/lib/python3.11/site-packages/geopy/geocoders/base.py", line 368, in _call_geocoder
    result = self.adapter.get_json(url, timeout=timeout, headers=req_headers)
             ^^^^^^^^^^^^^^^^^^^^^^^^^^^^^^^^^^^^^^^^^^^^^^^^^^^^^^^^^^^^^^^^
  File "/Users/apple2015/Documents/Work/Bolsover District Council/Project/.venv/lib/python3.11/site-packages/geopy/adapters.py", line 472, in get_json
    resp = self._request(url, timeout=timeout, headers=headers)
           ^^^^^^^^^^^^^^^^^^^^^^^^^^^^^^^^^^^^^^^^^^^^^^^^^^^^
  File "/Users/apple2015/Documents/Work/Bolsover District Council/Project/.venv/lib/python3.11/site-packages/geopy/adapters.py", line 494, in _request
    raise GeocoderUnavailable(message)
geopy.exc.GeocoderUnavailable: HTTPSConnectionPool(host='nominatim.openstreetmap.org', port=443): Max retries exceeded with url: /search?q=S44+8NB%2C+Bolsover+District%2C+UK&format=json&limit=1 (Caused by ReadTimeoutError("HTTPSConnectionPool(host='nominatim.openstreetmap.org', port=443): Read timed out. (read timeout=1)"))
2025-04-07 00:18:39,913 - urllib3.connectionpool - WARNING - Retrying (Retry(total=1, connect=None, read=None, redirect=None, status=None)) after connection broken by 'ReadTimeoutError("HTTPSConnectionPool(host='nominatim.openstreetmap.org', port=443): Read timed out. (read timeout=1)")': /search?q=S44+2LM%2C+Bolsover+District%2C+UK&format=json&limit=1
2025-04-07 00:18:45,835 - urllib3.connectionpool - WARNING - Retrying (Retry(total=1, connect=None, read=None, redirect=None, status=None)) after connection broken by 'ReadTimeoutError("HTTPSConnectionPool(host='nominatim.openstreetmap.org', port=443): Read timed out. (read timeout=1)")': /search?q=S44+2LM&format=json&limit=1
2025-04-07 00:18:47,803 - urllib3.connectionpool - WARNING - Retrying (Retry(total=1, connect=None, read=None, redirect=None, status=None)) after connection broken by 'ReadTimeoutError("HTTPSConnectionPool(host='nominatim.openstreetmap.org', port=443): Read timed out. (read timeout=1)")': /search?q=77+Redwood+Road%2C+Bolsover%2C+S44+2LM%2C+Bolsover+District%2C+UK&format=json&limit=1
2025-04-07 00:18:48,870 - urllib3.connectionpool - WARNING - Retrying (Retry(total=0, connect=None, read=None, redirect=None, status=None)) after connection broken by 'ReadTimeoutError("HTTPSConnectionPool(host='nominatim.openstreetmap.org', port=443): Read timed out. (read timeout=1)")': /search?q=77+Redwood+Road%2C+Bolsover%2C+S44+2LM%2C+Bolsover+District%2C+UK&format=json&limit=1
2025-04-07 00:18:49,936 - processing.geocoding - ERROR - Address geocoding error: HTTPSConnectionPool(host='nominatim.openstreetmap.org', port=443): Max retries exceeded with url: /search?q=77+Redwood+Road%2C+Bolsover%2C+S44+2LM%2C+Bolsover+District%2C+UK&format=json&limit=1 (Caused by ReadTimeoutError("HTTPSConnectionPool(host='nominatim.openstreetmap.org', port=443): Read timed out. (read timeout=1)"))
Traceback (most recent call last):
  File "/Users/apple2015/Documents/Work/Bolsover District Council/Project/.venv/lib/python3.11/site-packages/urllib3/connectionpool.py", line 534, in _make_request
    response = conn.getresponse()
               ^^^^^^^^^^^^^^^^^^
  File "/Users/apple2015/Documents/Work/Bolsover District Council/Project/.venv/lib/python3.11/site-packages/urllib3/connection.py", line 516, in getresponse
    httplib_response = super().getresponse()
                       ^^^^^^^^^^^^^^^^^^^^^
  File "/Library/Frameworks/Python.framework/Versions/3.11/lib/python3.11/http/client.py", line 1378, in getresponse
    response.begin()
  File "/Library/Frameworks/Python.framework/Versions/3.11/lib/python3.11/http/client.py", line 318, in begin
    version, status, reason = self._read_status()
                              ^^^^^^^^^^^^^^^^^^^
  File "/Library/Frameworks/Python.framework/Versions/3.11/lib/python3.11/http/client.py", line 279, in _read_status
    line = str(self.fp.readline(_MAXLINE + 1), "iso-8859-1")
               ^^^^^^^^^^^^^^^^^^^^^^^^^^^^^^
  File "/Library/Frameworks/Python.framework/Versions/3.11/lib/python3.11/socket.py", line 706, in readinto
    return self._sock.recv_into(b)
           ^^^^^^^^^^^^^^^^^^^^^^^
  File "/Library/Frameworks/Python.framework/Versions/3.11/lib/python3.11/ssl.py", line 1278, in recv_into
    return self.read(nbytes, buffer)
           ^^^^^^^^^^^^^^^^^^^^^^^^^
  File "/Library/Frameworks/Python.framework/Versions/3.11/lib/python3.11/ssl.py", line 1134, in read
    return self._sslobj.read(len, buffer)
           ^^^^^^^^^^^^^^^^^^^^^^^^^^^^^^
TimeoutError: The read operation timed out

The above exception was the direct cause of the following exception:

Traceback (most recent call last):
  File "/Users/apple2015/Documents/Work/Bolsover District Council/Project/.venv/lib/python3.11/site-packages/urllib3/connectionpool.py", line 787, in urlopen
    response = self._make_request(
               ^^^^^^^^^^^^^^^^^^^
  File "/Users/apple2015/Documents/Work/Bolsover District Council/Project/.venv/lib/python3.11/site-packages/urllib3/connectionpool.py", line 536, in _make_request
    self._raise_timeout(err=e, url=url, timeout_value=read_timeout)
  File "/Users/apple2015/Documents/Work/Bolsover District Council/Project/.venv/lib/python3.11/site-packages/urllib3/connectionpool.py", line 367, in _raise_timeout
    raise ReadTimeoutError(
urllib3.exceptions.ReadTimeoutError: HTTPSConnectionPool(host='nominatim.openstreetmap.org', port=443): Read timed out. (read timeout=1)

The above exception was the direct cause of the following exception:

Traceback (most recent call last):
  File "/Users/apple2015/Documents/Work/Bolsover District Council/Project/.venv/lib/python3.11/site-packages/requests/adapters.py", line 667, in send
    resp = conn.urlopen(
           ^^^^^^^^^^^^^
  File "/Users/apple2015/Documents/Work/Bolsover District Council/Project/.venv/lib/python3.11/site-packages/urllib3/connectionpool.py", line 871, in urlopen
    return self.urlopen(
           ^^^^^^^^^^^^^
  File "/Users/apple2015/Documents/Work/Bolsover District Council/Project/.venv/lib/python3.11/site-packages/urllib3/connectionpool.py", line 871, in urlopen
    return self.urlopen(
           ^^^^^^^^^^^^^
  File "/Users/apple2015/Documents/Work/Bolsover District Council/Project/.venv/lib/python3.11/site-packages/urllib3/connectionpool.py", line 841, in urlopen
    retries = retries.increment(
              ^^^^^^^^^^^^^^^^^^
  File "/Users/apple2015/Documents/Work/Bolsover District Council/Project/.venv/lib/python3.11/site-packages/urllib3/util/retry.py", line 519, in increment
    raise MaxRetryError(_pool, url, reason) from reason  # type: ignore[arg-type]
    ^^^^^^^^^^^^^^^^^^^^^^^^^^^^^^^^^^^^^^^^^^^^^^^^^^^
urllib3.exceptions.MaxRetryError: HTTPSConnectionPool(host='nominatim.openstreetmap.org', port=443): Max retries exceeded with url: /search?q=77+Redwood+Road%2C+Bolsover%2C+S44+2LM%2C+Bolsover+District%2C+UK&format=json&limit=1 (Caused by ReadTimeoutError("HTTPSConnectionPool(host='nominatim.openstreetmap.org', port=443): Read timed out. (read timeout=1)"))

During handling of the above exception, another exception occurred:

Traceback (most recent call last):
  File "/Users/apple2015/Documents/Work/Bolsover District Council/Project/.venv/lib/python3.11/site-packages/geopy/adapters.py", line 482, in _request
    resp = self.session.get(url, timeout=timeout, headers=headers)
           ^^^^^^^^^^^^^^^^^^^^^^^^^^^^^^^^^^^^^^^^^^^^^^^^^^^^^^^
  File "/Users/apple2015/Documents/Work/Bolsover District Council/Project/.venv/lib/python3.11/site-packages/requests/sessions.py", line 602, in get
    return self.request("GET", url, **kwargs)
           ^^^^^^^^^^^^^^^^^^^^^^^^^^^^^^^^^^
  File "/Users/apple2015/Documents/Work/Bolsover District Council/Project/.venv/lib/python3.11/site-packages/requests/sessions.py", line 589, in request
    resp = self.send(prep, **send_kwargs)
           ^^^^^^^^^^^^^^^^^^^^^^^^^^^^^^
  File "/Users/apple2015/Documents/Work/Bolsover District Council/Project/.venv/lib/python3.11/site-packages/requests/sessions.py", line 703, in send
    r = adapter.send(request, **kwargs)
        ^^^^^^^^^^^^^^^^^^^^^^^^^^^^^^^
  File "/Users/apple2015/Documents/Work/Bolsover District Council/Project/.venv/lib/python3.11/site-packages/requests/adapters.py", line 700, in send
    raise ConnectionError(e, request=request)
requests.exceptions.ConnectionError: HTTPSConnectionPool(host='nominatim.openstreetmap.org', port=443): Max retries exceeded with url: /search?q=77+Redwood+Road%2C+Bolsover%2C+S44+2LM%2C+Bolsover+District%2C+UK&format=json&limit=1 (Caused by ReadTimeoutError("HTTPSConnectionPool(host='nominatim.openstreetmap.org', port=443): Read timed out. (read timeout=1)"))

During handling of the above exception, another exception occurred:

Traceback (most recent call last):
  File "/Users/apple2015/Documents/Work/Bolsover District Council/Project/processing/geocoding.py", line 94, in geocode_location
    location = geolocator.geocode(f"{location_name}, Bolsover District, UK", exactly_one=True)
               ^^^^^^^^^^^^^^^^^^^^^^^^^^^^^^^^^^^^^^^^^^^^^^^^^^^^^^^^^^^^^^^^^^^^^^^^^^^^^^^
  File "/Users/apple2015/Documents/Work/Bolsover District Council/Project/.venv/lib/python3.11/site-packages/geopy/geocoders/nominatim.py", line 297, in geocode
    return self._call_geocoder(url, callback, timeout=timeout)
           ^^^^^^^^^^^^^^^^^^^^^^^^^^^^^^^^^^^^^^^^^^^^^^^^^^^
  File "/Users/apple2015/Documents/Work/Bolsover District Council/Project/.venv/lib/python3.11/site-packages/geopy/geocoders/base.py", line 368, in _call_geocoder
    result = self.adapter.get_json(url, timeout=timeout, headers=req_headers)
             ^^^^^^^^^^^^^^^^^^^^^^^^^^^^^^^^^^^^^^^^^^^^^^^^^^^^^^^^^^^^^^^^
  File "/Users/apple2015/Documents/Work/Bolsover District Council/Project/.venv/lib/python3.11/site-packages/geopy/adapters.py", line 472, in get_json
    resp = self._request(url, timeout=timeout, headers=headers)
           ^^^^^^^^^^^^^^^^^^^^^^^^^^^^^^^^^^^^^^^^^^^^^^^^^^^^
  File "/Users/apple2015/Documents/Work/Bolsover District Council/Project/.venv/lib/python3.11/site-packages/geopy/adapters.py", line 494, in _request
    raise GeocoderUnavailable(message)
geopy.exc.GeocoderUnavailable: HTTPSConnectionPool(host='nominatim.openstreetmap.org', port=443): Max retries exceeded with url: /search?q=77+Redwood+Road%2C+Bolsover%2C+S44+2LM%2C+Bolsover+District%2C+UK&format=json&limit=1 (Caused by ReadTimeoutError("HTTPSConnectionPool(host='nominatim.openstreetmap.org', port=443): Read timed out. (read timeout=1)"))
2025-04-07 00:18:51,787 - urllib3.connectionpool - WARNING - Retrying (Retry(total=1, connect=None, read=None, redirect=None, status=None)) after connection broken by 'ReadTimeoutError("HTTPSConnectionPool(host='nominatim.openstreetmap.org', port=443): Read timed out. (read timeout=1)")': /search?q=3+Mill+Lane%2C+Bolsover%2C+S44+8NB%2C+Bolsover+District%2C+UK&format=json&limit=1
2025-04-07 00:18:52,921 - urllib3.connectionpool - WARNING - Retrying (Retry(total=0, connect=None, read=None, redirect=None, status=None)) after connection broken by 'ReadTimeoutError("HTTPSConnectionPool(host='nominatim.openstreetmap.org', port=443): Read timed out. (read timeout=1)")': /search?q=3+Mill+Lane%2C+Bolsover%2C+S44+8NB%2C+Bolsover+District%2C+UK&format=json&limit=1
2025-04-07 00:18:54,028 - processing.geocoding - ERROR - Address geocoding error: HTTPSConnectionPool(host='nominatim.openstreetmap.org', port=443): Max retries exceeded with url: /search?q=3+Mill+Lane%2C+Bolsover%2C+S44+8NB%2C+Bolsover+District%2C+UK&format=json&limit=1 (Caused by ReadTimeoutError("HTTPSConnectionPool(host='nominatim.openstreetmap.org', port=443): Read timed out. (read timeout=1)"))
Traceback (most recent call last):
  File "/Users/apple2015/Documents/Work/Bolsover District Council/Project/.venv/lib/python3.11/site-packages/urllib3/connectionpool.py", line 534, in _make_request
    response = conn.getresponse()
               ^^^^^^^^^^^^^^^^^^
  File "/Users/apple2015/Documents/Work/Bolsover District Council/Project/.venv/lib/python3.11/site-packages/urllib3/connection.py", line 516, in getresponse
    httplib_response = super().getresponse()
                       ^^^^^^^^^^^^^^^^^^^^^
  File "/Library/Frameworks/Python.framework/Versions/3.11/lib/python3.11/http/client.py", line 1378, in getresponse
    response.begin()
  File "/Library/Frameworks/Python.framework/Versions/3.11/lib/python3.11/http/client.py", line 318, in begin
    version, status, reason = self._read_status()
                              ^^^^^^^^^^^^^^^^^^^
  File "/Library/Frameworks/Python.framework/Versions/3.11/lib/python3.11/http/client.py", line 279, in _read_status
    line = str(self.fp.readline(_MAXLINE + 1), "iso-8859-1")
               ^^^^^^^^^^^^^^^^^^^^^^^^^^^^^^
  File "/Library/Frameworks/Python.framework/Versions/3.11/lib/python3.11/socket.py", line 706, in readinto
    return self._sock.recv_into(b)
           ^^^^^^^^^^^^^^^^^^^^^^^
  File "/Library/Frameworks/Python.framework/Versions/3.11/lib/python3.11/ssl.py", line 1278, in recv_into
    return self.read(nbytes, buffer)
           ^^^^^^^^^^^^^^^^^^^^^^^^^
  File "/Library/Frameworks/Python.framework/Versions/3.11/lib/python3.11/ssl.py", line 1134, in read
    return self._sslobj.read(len, buffer)
           ^^^^^^^^^^^^^^^^^^^^^^^^^^^^^^
TimeoutError: The read operation timed out

The above exception was the direct cause of the following exception:

Traceback (most recent call last):
  File "/Users/apple2015/Documents/Work/Bolsover District Council/Project/.venv/lib/python3.11/site-packages/urllib3/connectionpool.py", line 787, in urlopen
    response = self._make_request(
               ^^^^^^^^^^^^^^^^^^^
  File "/Users/apple2015/Documents/Work/Bolsover District Council/Project/.venv/lib/python3.11/site-packages/urllib3/connectionpool.py", line 536, in _make_request
    self._raise_timeout(err=e, url=url, timeout_value=read_timeout)
  File "/Users/apple2015/Documents/Work/Bolsover District Council/Project/.venv/lib/python3.11/site-packages/urllib3/connectionpool.py", line 367, in _raise_timeout
    raise ReadTimeoutError(
urllib3.exceptions.ReadTimeoutError: HTTPSConnectionPool(host='nominatim.openstreetmap.org', port=443): Read timed out. (read timeout=1)

The above exception was the direct cause of the following exception:

Traceback (most recent call last):
  File "/Users/apple2015/Documents/Work/Bolsover District Council/Project/.venv/lib/python3.11/site-packages/requests/adapters.py", line 667, in send
    resp = conn.urlopen(
           ^^^^^^^^^^^^^
  File "/Users/apple2015/Documents/Work/Bolsover District Council/Project/.venv/lib/python3.11/site-packages/urllib3/connectionpool.py", line 871, in urlopen
    return self.urlopen(
           ^^^^^^^^^^^^^
  File "/Users/apple2015/Documents/Work/Bolsover District Council/Project/.venv/lib/python3.11/site-packages/urllib3/connectionpool.py", line 871, in urlopen
    return self.urlopen(
           ^^^^^^^^^^^^^
  File "/Users/apple2015/Documents/Work/Bolsover District Council/Project/.venv/lib/python3.11/site-packages/urllib3/connectionpool.py", line 841, in urlopen
    retries = retries.increment(
              ^^^^^^^^^^^^^^^^^^
  File "/Users/apple2015/Documents/Work/Bolsover District Council/Project/.venv/lib/python3.11/site-packages/urllib3/util/retry.py", line 519, in increment
    raise MaxRetryError(_pool, url, reason) from reason  # type: ignore[arg-type]
    ^^^^^^^^^^^^^^^^^^^^^^^^^^^^^^^^^^^^^^^^^^^^^^^^^^^
urllib3.exceptions.MaxRetryError: HTTPSConnectionPool(host='nominatim.openstreetmap.org', port=443): Max retries exceeded with url: /search?q=3+Mill+Lane%2C+Bolsover%2C+S44+8NB%2C+Bolsover+District%2C+UK&format=json&limit=1 (Caused by ReadTimeoutError("HTTPSConnectionPool(host='nominatim.openstreetmap.org', port=443): Read timed out. (read timeout=1)"))

During handling of the above exception, another exception occurred:

Traceback (most recent call last):
  File "/Users/apple2015/Documents/Work/Bolsover District Council/Project/.venv/lib/python3.11/site-packages/geopy/adapters.py", line 482, in _request
    resp = self.session.get(url, timeout=timeout, headers=headers)
           ^^^^^^^^^^^^^^^^^^^^^^^^^^^^^^^^^^^^^^^^^^^^^^^^^^^^^^^
  File "/Users/apple2015/Documents/Work/Bolsover District Council/Project/.venv/lib/python3.11/site-packages/requests/sessions.py", line 602, in get
    return self.request("GET", url, **kwargs)
           ^^^^^^^^^^^^^^^^^^^^^^^^^^^^^^^^^^
  File "/Users/apple2015/Documents/Work/Bolsover District Council/Project/.venv/lib/python3.11/site-packages/requests/sessions.py", line 589, in request
    resp = self.send(prep, **send_kwargs)
           ^^^^^^^^^^^^^^^^^^^^^^^^^^^^^^
  File "/Users/apple2015/Documents/Work/Bolsover District Council/Project/.venv/lib/python3.11/site-packages/requests/sessions.py", line 703, in send
    r = adapter.send(request, **kwargs)
        ^^^^^^^^^^^^^^^^^^^^^^^^^^^^^^^
  File "/Users/apple2015/Documents/Work/Bolsover District Council/Project/.venv/lib/python3.11/site-packages/requests/adapters.py", line 700, in send
    raise ConnectionError(e, request=request)
requests.exceptions.ConnectionError: HTTPSConnectionPool(host='nominatim.openstreetmap.org', port=443): Max retries exceeded with url: /search?q=3+Mill+Lane%2C+Bolsover%2C+S44+8NB%2C+Bolsover+District%2C+UK&format=json&limit=1 (Caused by ReadTimeoutError("HTTPSConnectionPool(host='nominatim.openstreetmap.org', port=443): Read timed out. (read timeout=1)"))

During handling of the above exception, another exception occurred:

Traceback (most recent call last):
  File "/Users/apple2015/Documents/Work/Bolsover District Council/Project/processing/geocoding.py", line 94, in geocode_location
    location = geolocator.geocode(f"{location_name}, Bolsover District, UK", exactly_one=True)
               ^^^^^^^^^^^^^^^^^^^^^^^^^^^^^^^^^^^^^^^^^^^^^^^^^^^^^^^^^^^^^^^^^^^^^^^^^^^^^^^
  File "/Users/apple2015/Documents/Work/Bolsover District Council/Project/.venv/lib/python3.11/site-packages/geopy/geocoders/nominatim.py", line 297, in geocode
    return self._call_geocoder(url, callback, timeout=timeout)
           ^^^^^^^^^^^^^^^^^^^^^^^^^^^^^^^^^^^^^^^^^^^^^^^^^^^
  File "/Users/apple2015/Documents/Work/Bolsover District Council/Project/.venv/lib/python3.11/site-packages/geopy/geocoders/base.py", line 368, in _call_geocoder
    result = self.adapter.get_json(url, timeout=timeout, headers=req_headers)
             ^^^^^^^^^^^^^^^^^^^^^^^^^^^^^^^^^^^^^^^^^^^^^^^^^^^^^^^^^^^^^^^^
  File "/Users/apple2015/Documents/Work/Bolsover District Council/Project/.venv/lib/python3.11/site-packages/geopy/adapters.py", line 472, in get_json
    resp = self._request(url, timeout=timeout, headers=headers)
           ^^^^^^^^^^^^^^^^^^^^^^^^^^^^^^^^^^^^^^^^^^^^^^^^^^^^
  File "/Users/apple2015/Documents/Work/Bolsover District Council/Project/.venv/lib/python3.11/site-packages/geopy/adapters.py", line 494, in _request
    raise GeocoderUnavailable(message)
geopy.exc.GeocoderUnavailable: HTTPSConnectionPool(host='nominatim.openstreetmap.org', port=443): Max retries exceeded with url: /search?q=3+Mill+Lane%2C+Bolsover%2C+S44+8NB%2C+Bolsover+District%2C+UK&format=json&limit=1 (Caused by ReadTimeoutError("HTTPSConnectionPool(host='nominatim.openstreetmap.org', port=443): Read timed out. (read timeout=1)"))
2025-04-07 00:18:55,907 - urllib3.connectionpool - WARNING - Retrying (Retry(total=1, connect=None, read=None, redirect=None, status=None)) after connection broken by 'ReadTimeoutError("HTTPSConnectionPool(host='nominatim.openstreetmap.org', port=443): Read timed out. (read timeout=1)")': /search?q=S44+4HI&format=json&limit=1
2025-04-07 00:18:59,876 - urllib3.connectionpool - WARNING - Retrying (Retry(total=1, connect=None, read=None, redirect=None, status=None)) after connection broken by 'ReadTimeoutError("HTTPSConnectionPool(host='nominatim.openstreetmap.org', port=443): Read timed out. (read timeout=1)")': /search?q=S44+5FG%2C+Bolsover+District%2C+UK&format=json&limit=1
2025-04-07 00:19:04,801 - models.classification - INFO - Starting document classification
2025-04-07 00:19:04,803 - models.load_models - INFO - Loading Zero-Shot Classifier model
2025-04-07 00:19:07,699 - models.load_models - INFO - Zero-Shot Classifier model loaded successfully
2025-04-07 00:19:19,631 - models.classification - INFO - Document classified as: Local Problem
2025-04-07 00:19:19,641 - models.load_models - INFO - Loading Sentiment Analysis model
2025-04-07 00:19:20,295 - models.load_models - INFO - Sentiment Analysis model loaded successfully
2025-04-07 00:19:21,885 - models.sentiment - INFO - Analyzed sentiment: POSITIVE (confidence: 0.92)
2025-04-07 00:19:21,944 - models.classification - INFO - Starting document classification
2025-04-07 00:19:23,968 - models.classification - INFO - Document classified as: Local Problem
2025-04-07 00:19:24,149 - models.sentiment - INFO - Analyzed sentiment: POSITIVE (confidence: 0.99)
2025-04-07 00:19:24,154 - models.classification - INFO - Starting document classification
2025-04-07 00:19:26,179 - models.classification - INFO - Document classified as: Local Problem
2025-04-07 00:19:26,366 - models.sentiment - INFO - Analyzed sentiment: POSITIVE (confidence: 0.88)
2025-04-07 00:19:26,375 - models.classification - INFO - Starting document classification
2025-04-07 00:19:28,914 - models.classification - INFO - Document classified as: Local Problem
2025-04-07 00:19:29,146 - models.sentiment - INFO - Analyzed sentiment: POSITIVE (confidence: 0.99)
2025-04-07 00:19:29,153 - models.classification - INFO - Starting document classification
2025-04-07 00:19:31,071 - models.classification - INFO - Document classified as: Local Problem
2025-04-07 00:19:31,266 - models.sentiment - INFO - Analyzed sentiment: POSITIVE (confidence: 0.99)
2025-04-07 00:19:31,275 - models.classification - INFO - Starting document classification
2025-04-07 00:19:33,191 - models.classification - INFO - Document classified as: Local Problem
2025-04-07 00:19:33,377 - models.sentiment - INFO - Analyzed sentiment: NEGATIVE (confidence: 0.99)
2025-04-07 00:19:33,385 - models.classification - INFO - Starting document classification
2025-04-07 00:19:35,161 - models.classification - INFO - Document classified as: Local Problem
2025-04-07 00:19:35,332 - models.sentiment - INFO - Analyzed sentiment: POSITIVE (confidence: 0.93)
2025-04-07 00:19:35,341 - models.classification - INFO - Starting document classification
2025-04-07 00:19:37,605 - models.classification - INFO - Document classified as: Local Problem
2025-04-07 00:19:37,760 - models.sentiment - INFO - Analyzed sentiment: NEGATIVE (confidence: 0.76)
2025-04-07 00:19:37,765 - models.classification - INFO - Starting document classification
2025-04-07 00:19:39,437 - models.classification - INFO - Document classified as: Local Problem
2025-04-07 00:19:39,589 - models.sentiment - INFO - Analyzed sentiment: POSITIVE (confidence: 1.00)
2025-04-07 00:19:39,597 - models.classification - INFO - Starting document classification
2025-04-07 00:19:41,479 - models.classification - INFO - Document classified as: Local Problem
2025-04-07 00:19:41,665 - models.sentiment - INFO - Analyzed sentiment: POSITIVE (confidence: 0.85)
2025-04-07 00:19:41,672 - models.classification - INFO - Starting document classification
2025-04-07 00:19:43,702 - models.classification - INFO - Document classified as: Local Problem
2025-04-07 00:19:43,857 - models.sentiment - INFO - Analyzed sentiment: NEGATIVE (confidence: 0.73)
2025-04-07 00:19:43,866 - models.classification - INFO - Starting document classification
2025-04-07 00:19:45,520 - models.classification - INFO - Document classified as: New Initiatives
2025-04-07 00:19:45,692 - models.sentiment - INFO - Analyzed sentiment: POSITIVE (confidence: 1.00)
